Workbook
Name Parcial: 'FORMATO-CHECK-LIST'!$D$19

Sheet FORMATO_LIQUIDACION
A1: LIQUIDACION FINAL
A4: Reclamo | B4: 123456
A5: ZC | B5: 5456
A6: Asegurado | B6: 1234656
A7: NIT / CC | B7: 123566
A8: Poliza No | B8: ksk4
A9: Fecha de Siniestro | B9: 46154
A10: Cobertura | B10: 1212121
A11: Deducible | B11: 0% del Valor de la Pérdida Mínimo 0 SMMLV
A13: CONCEPTO | B13: DETALLE | H13: VALOR
B14: Cualquier cosa | H14: 10000
B15: Cualquier cosa | H15: 1000000
B16: Cualquier cosa | H16: 100000000
A26: TOTAL PERDIDA | H26: =SUM(H14:H25) -> 101010000
A27: DEDUCIBLE | B27: =B11 -> 0% del Valor de la Pérdida Mínimo 0 SMMLV | C27: 0.1 | D27: =H26*C27 -> 10101000 | E27: VALOR | F27: 1 | G27: 10200000 | H27: =MAX(D27,G27) -> 10200000
A28: TOTAL INDEMNIZACION | H28: =H26-H27 -> 90810000
B30: MONEDA | D30: COP | E30: TRM
A37: ELABORADO POR:

Sheet FORMATO-CHECK-LIST
B2: FORMATO ÚNICO ATENCIÓN DE RECLAMOS EXPRESS PROPERTY
O3: Aplica
O4: No Aplica
O6: Parcial
B7: INFORMACIÓN GENERAL DEL RECLAMO | O7: Total
O8: No aplica
C9: Fecha: | D9: =TODAY() -> 46211
C10: ZC: | D10: =FORMATO_LIQUIDACION!B5 -> 5456
C11: STRO: | D11: =FORMATO_LIQUIDACION!B8 -> ksk4
C12: Tipo de producto: | D12: TRDM
C13: Número de póliza: | D13: =FORMATO_LIQUIDACION!B8 -> ksk4
C14: Asegurado: | D14: =FORMATO_LIQUIDACION!B6 -> 1234656
C15: Vigencia de la poliza: | D15: 45789 | E15: al | F15: 46157
C16: D.O.L: | D16: =FORMATO_LIQUIDACION!B9 -> 46154
C17: Riesgo asegurado: | D17: =D14 -> 1234656
C18: Cobertura afectada: | D18: Parcial
C19: Garantias: | D19: Aplica
C20: Exclusiones: | D20: Aplica
C21: Objeción: | D21: No Aplica
C22: Tipo de pérdida: | D22: Parcial
C23: Aplica demérito: | D23: No Aplica
C24: Limite o valor asegurado:
C25: Pérdida ajustada: | E25: =[1]FORMATO_LIQUIDACION!G25 -> 101010000
C26: Deducible: | E26: =[1]FORMATO_LIQUIDACION!F26 -> 1000000
C27: Valor a indemnizar: | E27: =[1]FORMATO_LIQUIDACION!G27 -> 95959500
C28: Salvamento: | D28: No Aplica | E28: MOTOR Y CO
C29: Recobro: | D29: No Aplica
C30: Indicadores de fraude: | D30: No Aplica
C32: Breve descripción del evento:
C34: Ajustador - Gabriel Moremo
B36: DOCUMENTOS DE SOPORTE
C38: Comunicaciòn del asegurado donde indique las circunstancias de tiempo, modo y lugar en que ocurrieron los hechos | F38: TRUE
C39: Informe técnico de firma especializada acerca del alcance de los daños y causa de los mismos indicando la posibilidad de reparación | E39: Aplica | F39: TRUE
C40: Factura de adquisicion y/o Certificación emitida por el Contador o Revisor fiscal del generador, indicando (fecha de adquisicion, valor hurtado, valor costo de las mercancías, valor del bien afectado) | F40: TRUE
C41: Cotizacion y/o Factura de reparación o reposición del bien afectado por uno de iguales o similares características (discriminando mano de obra y materiales) | F41: TRUE
C42: Registro fotográfico o fílmico de los bienes afectados | F42: TRUE
C43: Denuncia Penal instaurada ante autoridad competente | F43: TRUE
C44: Hoja de vida de la máquina que incluya la tres ultimas bitácoras de mantenimiento de la máquina previo al siniestro | F44: TRUE
C46: Porcentaje de tareas finalizadas | E46: =COUNTIF(F38:F44,TRUE)/COUNTA(C38:C44) -> 1
C48: ¿el reclamo está formalizado? | E48: =IF(E46=1,"Sí","No") -> Sí
...

Sheet SALVAMENTO
F1: Formato Salvamentos
B6: Poliza | H6: =FORMATO_LIQUIDACION!B8 -> ksk4
B8: Reclamo | H8: =FORMATO_LIQUIDACION!B4 -> 123456
B10: Sub-tarea | H10: SALVAMENTO
B12: Asegurado | H12: =FORMATO_LIQUIDACION!B6 -> 1234656
C14: Informacion de Salvamento
J16: COMENTARIOS
C17: Descripcion Salvamento | J17: ='FORMATO-CHECK-LIST'!E28 -> MOTOR Y CO
C19: Cantidad (unidades) | J19: 1
C22: Marca salvamento | J22: N/D
C24: Serial salvamento | J24: N/D
C26: Especificacion del daño y estado actual del salvamento
C29: Ubicación (Direccion y ciudad)
C32: Contacto persona quien entrega
C35: Salvamento nacionalizado | J35: SI | L35: FALSE | N35: NO | P35: FALSE
C38: Genera costos por custodia | J38: SI | L38: FALSE | N38: NO | P38: FALSE | R38: Valor | T38: 0
C41: Registro fotografico | J41: SI | L41: FALSE | N41: NO | P41: FALSE
C44: Indemnizado | J44: SI | L44: FALSE | N44: NO | P44: FALSE | R44: Valor | T44: =[1]FORMATO_LIQUIDACION!G27 -> 95959500
C46: Se solicito oferta Non Cash | J46: SI | L46: FALSE | N46: NO | P46: FALSE | R46: Valor
C48: Comentarios salvamento
B52: NOTAS:
B53: 1. Todo salvamento debe contar registro fotográfico actualizado y debe estar cargado al respectivo ZC.
B54: 2. En la descripción del salvamento y de aplicar debe quedar relacionada la marca y serial del equipo.
B55: 3. En caso de que el salvamento corresponda a grado alimenticio o de consumo humano se debe notificar por correo para dar prioridad al mismo.
B57: 4. En las especificaciones del daño se debe dejar estipulado a que correspondió el daño y si el salvamento presenta algún tipo de despiece realizado que hubiera podido afectar el estado del salvamento.
B60: 5. En la casilla de comentarios se deben dejar observaciones adicionales, tales como posibles valores de venta, si es recomendable realizar disposición final del mismo, etc.
